<?xml version="1.0" encoding="utf-8"?>
<!-- This URDF was automatically created by SolidWorks to URDF Exporter! Originally created by Stephen Brawner (brawner@gmail.com) 
     Commit Version: 1.6.0-4-g7f85cfe  Build Version: 1.6.7995.38578
     For more information, please see http://wiki.ros.org/sw_urdf_exporter -->
<robot
  name="ar2_robot">
  
  <link name="world"/>
  
  <joint name="base_joint" type="fixed">
	<parent link="world"/>
	<child link="Base"/>
	<origin rpy="1.5708 0 0" xyz="0.0 0.0 0.01"/>
  </joint>
  
  <link
    name="Base">
    <inertial>
      <origin
        xyz="-0.047956 0.030971 4.1806E-06"
        rpy="0 0 0" />
      <mass
        value="0.79159" />
      <inertia
        ixx="0.00095033"
        ixy="2.9437E-06"
        ixz="3.7589E-07"
        iyy="0.0025623"
        iyz="5.7522E-08"
        izz="0.0017041" />
    </inertial>
    <visual>
      <origin
        xyz="0 0 0"
        rpy="0 0 0" />
      <geometry>
        <mesh
          filename="package://ar2_robot/meshes/Base.STL" />
      </geometry>
      <material
        name="">
        <color
          rgba="0.44706 0.47451 0.50196 1" />
      </material>
    </visual>
    <collision>
      <origin
        xyz="0 0 0"
        rpy="0 0 0" />
      <geometry>
        <mesh
          filename="package://ar2_robot/meshes/Base.STL" />
      </geometry>
    </collision>
  </link>
  <link
    name="L1">
    <inertial>
      <origin
        xyz="0.043178 0.11684 0.020606"
        rpy="0 0 0" />
      <mass
        value="0.89271" />
      <inertia
        ixx="0.00089563"
        ixy="-3.568E-05"
        ixz="-7.5709E-06"
        iyy="0.00087156"
        iyz="-1.941E-06"
        izz="0.00079881" />
    </inertial>
    <visual>
      <origin
        xyz="0 0 0"
        rpy="0 0 0" />
      <geometry>
        <mesh
          filename="package://ar2_robot/meshes/L1.STL" />
      </geometry>
      <material
        name="">
        <color
          rgba="0.79216 0.81961 0.93333 1" />
      </material>
    </visual>
    <collision>
      <origin
        xyz="0 0 0"
        rpy="0 0 0" />
      <geometry>
        <mesh
          filename="package://ar2_robot/meshes/L1.STL" />
      </geometry>
    </collision>
  </link>
  <joint
    name="J1"
    type="revolute">
    <origin
      xyz="0 0 0"
      rpy="0 0 0" />
    <parent
      link="Base" />
    <child
      link="L1" />
    <axis
      xyz="0 -1 0" />
    <limit
      lower="-3.142"
      upper="3.142"
      effort="300"
      velocity="3" />
  </joint>
  <link
    name="L2">
    <inertial>
      <origin
        xyz="0.00021277 -0.022592 -0.13662"
        rpy="0 0 0" />
      <mass
        value="0.60043" />
      <inertia
        ixx="0.0025639"
        ixy="6.398E-10"
        ixz="-2.6219E-06"
        iyy="0.002726"
        iyz="5.1152E-08"
        izz="0.00020847" />
    </inertial>
    <visual>
      <origin
        xyz="0 0 0"
        rpy="0 0 0" />
      <geometry>
        <mesh
          filename="package://ar2_robot/meshes/L2.STL" />
      </geometry>
      <material
        name="">
        <color
          rgba="0.44706 0.47451 0.50196 1" />
      </material>
    </visual>
    <collision>
      <origin
        xyz="0 0 0"
        rpy="0 0 0" />
      <geometry>
        <mesh
          filename="package://ar2_robot/meshes/L2.STL" />
      </geometry>
    </collision>
  </link>
  <joint
    name="J2"
    type="revolute">
    <origin
      xyz="0.064118 0.16067 -0.063319"
      rpy="-1.5708 -0.0004307 -3.1416" />
    <parent
      link="L1" />
    <child
      link="L2" />
    <axis
      xyz="0 -1 0" />
    <limit
      lower="-1.52"
      upper="1.52"
      effort="200"
      velocity="3" />
  </joint>
  <link
    name="L3">
    <inertial>
      <origin
        xyz="-0.012246 -0.058014 0.016206"
        rpy="0 0 0" />
      <mass
        value="0.35985" />
      <inertia
        ixx="0.00024987"
        ixy="5.8851E-08"
        ixz="-3.2649E-07"
        iyy="0.00025093"
        iyz="2.2271E-06"
        izz="9.3923E-05" />
    </inertial>
    <visual>
      <origin
        xyz="0 0 0"
        rpy="0 0 0" />
      <geometry>
        <mesh
          filename="package://ar2_robot/meshes/L3.STL" />
      </geometry>
      <material
        name="">
        <color
          rgba="0.44706 0.47451 0.50196 1" />
      </material>
    </visual>
    <collision>
      <origin
        xyz="0 0 0"
        rpy="0 0 0" />
      <geometry>
        <mesh
          filename="package://ar2_robot/meshes/L3.STL" />
      </geometry>
    </collision>
  </link>
  <joint
    name="J3"
    type="revolute">
    <origin
      xyz="0 -0.006 -0.30486"
      rpy="0 1.5708 0" />
    <parent
      link="L2" />
    <child
      link="L3" />
    <axis
      xyz="0 1 0" />
    <limit
      lower="-3.142"
      upper="3.142"
      effort="200"
      velocity="3" />
  </joint>
  <link
    name="L4">
    <inertial>
      <origin
        xyz="-0.00027059 0.090109 0.0021302"
        rpy="0 0 0" />
      <mass
        value="0.26277" />
      <inertia
        ixx="0.00040504"
        ixy="-2.7858E-07"
        ixz="-2.4376E-07"
        iyy="7.4494E-05"
        iyz="-5.3627E-07"
        izz="0.00044176" />
    </inertial>
    <visual>
      <origin
        xyz="0 0 0"
        rpy="0 0 0" />
      <geometry>
        <mesh
          filename="package://ar2_robot/meshes/L4.STL" />
      </geometry>
      <material
        name="">
        <color
          rgba="0.44706 0.47451 0.50196 1" />
      </material>
    </visual>
    <collision>
      <origin
        xyz="0 0 0"
        rpy="0 0 0" />
      <geometry>
        <mesh
          filename="package://ar2_robot/meshes/L4.STL" />
      </geometry>
    </collision>
  </link>
  <joint
    name="J4"
    type="revolute">
    <origin
      xyz="1.3711E-05 -0.0649 -0.035329"
      rpy="-1.5708 0 -0.0087908" />
    <parent
      link="L3" />
    <child
      link="L4" />
    <axis
      xyz="0 -1 0" />
    <limit
      lower="-3.142"
      upper="3.142"
      effort="200"
      velocity="3" />
  </joint>
  <link
    name="L5">
    <inertial>
      <origin
        xyz="0.01038 -0.041185 -0.0015562"
        rpy="0 0 0" />
      <mass
        value="0.13308" />
      <inertia
        ixx="2.7531E-05"
        ixy="7.1532E-08"
        ixz="1.0741E-06"
        iyy="4.6956E-05"
        iyz="5.8105E-09"
        izz="4.7362E-05" />
    </inertial>
    <visual>
      <origin
        xyz="0 0 0"
        rpy="0 0 0" />
      <geometry>
        <mesh
          filename="package://ar2_robot/meshes/L5.STL" />
      </geometry>
      <material
        name="">
        <color
          rgba="0.44706 0.47451 0.50196 1" />
      </material>
    </visual>
    <collision>
      <origin
        xyz="0 0 0"
        rpy="0 0 0" />
      <geometry>
        <mesh
          filename="package://ar2_robot/meshes/L5.STL" />
      </geometry>
    </collision>
  </link>
  <joint
    name="J5"
    type="revolute">
    <origin
      xyz="0 0.18709 0.04446"
      rpy="1.5708 0 0" />
    <parent
      link="L4" />
    <child
      link="L5" />
    <axis
      xyz="0 1 0" />
    <limit
      lower="-3.142"
      upper="3.142"
      effort="200"
      velocity="3" />
  </joint>
  <link
    name="L6">
    <inertial>
      <origin
        xyz="-6.3104E-05 0.01717 -3.4011E-05"
        rpy="0 0 0" />
      <mass
        value="0.032754" />
      <inertia
        ixx="5.6182E-06"
        ixy="-9.4627E-09"
        ixz="2.0257E-09"
        iyy="7.5493E-06"
        iyz="-1.6722E-09"
        izz="3.1805E-06" />
    </inertial>
    <visual>
      <origin
        xyz="0 0 0"
        rpy="0 0 0" />
      <geometry>
        <mesh
          filename="package://ar2_robot/meshes/L6.STL" />
      </geometry>
      <material
        name="">
        <color
          rgba="0.44706 0.47451 0.50196 1" />
      </material>
    </visual>
    <collision>
      <origin
        xyz="0 0 0"
        rpy="0 0 0" />
      <geometry>
        <mesh
          filename="package://ar2_robot/meshes/L6.STL" />
      </geometry>
    </collision>
  </link>
  <joint
    name="J6"
    type="revolute">
    <origin
      xyz="-0.020374 -0.045745 0.0010366"
      rpy="1.5793 1.52 -3.1331" />
    <parent
      link="L5" />
    <child
      link="L6" />
    <axis
      xyz="0 -1 0" />
    <limit
      lower="-3.142"
      upper="3.142"
      effort="300"
      velocity="3" />
  </joint>
  <link
    name="Claw_1">
    <inertial>
      <origin
        xyz="-0.00053649 -0.011369 -0.0035521"
        rpy="0 0 0" />
      <mass
        value="0.0050745" />
      <inertia
        ixx="3.0939E-07"
        ixy="-7.122E-09"
        ixz="3.5242E-09"
        iyy="3.0763E-07"
        iyz="3.8275E-08"
        izz="2.7958E-07" />
    </inertial>
    <visual>
      <origin
        xyz="0 0 0"
        rpy="0 0 0" />
      <geometry>
        <mesh
          filename="package://ar2_robot/meshes/Claw_1.STL" />
      </geometry>
      <material
        name="">
        <color
          rgba="0.79216 0.81961 0.93333 1" />
      </material>
    </visual>
    <collision>
      <origin
        xyz="0 0 0"
        rpy="0 0 0" />
      <geometry>
        <mesh
          filename="package://ar2_robot/meshes/Claw_1.STL" />
      </geometry>
    </collision>
  </link>
  <joint
    name="J7"
    type="prismatic">
    <origin
      xyz="-9.1987E-05 0.03627 0.023437"
      rpy="1.5708 -0.00083041 -0.050842" />
    <parent
      link="L6" />
    <child
      link="Claw_1" />
    <axis
      xyz="0 -1 0" />
    <limit
      lower="-0.01"
      upper="0"
      effort="100"
      velocity="3" />
  </joint>
  <link
    name="CLaw_2">
    <inertial>
      <origin
        xyz="1.823E-05 -0.011358 0.0037061"
        rpy="0 0 0" />
      <mass
        value="0.0050795" />
      <inertia
        ixx="3.0974E-07"
        ixy="1.1603E-08"
        ixz="6.6422E-09"
        iyy="3.0778E-07"
        iyz="-3.7594E-08"
        izz="2.8222E-07" />
    </inertial>
    <visual>
      <origin
        xyz="0 0 0"
        rpy="0 0 0" />
      <geometry>
        <mesh
          filename="package://ar2_robot/meshes/CLaw_2.STL" />
      </geometry>
      <material
        name="">
        <color
          rgba="0.79216 0.81961 0.93333 1" />
      </material>
    </visual>
    <collision>
      <origin
        xyz="0 0 0"
        rpy="0 0 0" />
      <geometry>
        <mesh
          filename="package://ar2_robot/meshes/CLaw_2.STL" />
      </geometry>
    </collision>
  </link>
  <joint
    name="J8"
    type="prismatic">
    <origin
      xyz="-5.402E-05 0.03627 -0.022225"
      rpy="-1.5708 -0.00083041 -0.050842" />
    <parent
      link="L6" />
    <child
      link="CLaw_2" />
    <axis
      xyz="0 -1 0" />
    <limit
      lower="-0.01"
      upper="0"
      effort="100"
      velocity="3" />
  </joint>
  <link name="camera_link">
    <visual>
        <geometry>
             <cylinder radius="0.005" length="0.01"/>
        </geometry>
     <material name="gray">
     <color rgba="0.5 0.5 0.5 1.0"/>
     </material>
    </visual>
</link>

<joint name="camera_joint" type="fixed">
    <parent link="L6"/>
    <child link="camera_link"/>
    <axis
      xyz="0 -1 0" />
    <origin xyz="0.02 0.02 0" rpy="0 0 1.5708"/>
</joint>

<link name="Claw_mid"/>  

<joint name="J_mid" type="fixed">
    <origin xyz="-0.00025913 -0.0113635 0.000077" rpy="0 0 0"/>
    <parent link="L6"/>
    <child link="Claw_mid"/>
</joint>

  <transmission name="link_1_trans">
	<type>transmission_interface/SimpleTransmission</type>
	<joint name="J1">
		<hardwareInterface>hardware_interface/PositionJointInterface</hardwareInterface>
	</joint>
	<actuator name="link_1_motor">
		<hardwareInterface>hardware_interface/PositionJointInterface</hardwareInterface>
		<mechanicalReduction>1</mechanicalReduction>
	</actuator>
  </transmission>
  
    <transmission name="link_2_trans">
	<type>transmission_interface/SimpleTransmission</type>
	<joint name="J2">
		<hardwareInterface>hardware_interface/PositionJointInterface</hardwareInterface>
	</joint>
	<actuator name="link_2_motor">
		<hardwareInterface>hardware_interface/PositionJointInterface</hardwareInterface>
		<mechanicalReduction>1</mechanicalReduction>
	</actuator>
  </transmission>
  
    <transmission name="link_3_trans">
	<type>transmission_interface/SimpleTransmission</type>
	<joint name="J3">
		<hardwareInterface>hardware_interface/PositionJointInterface</hardwareInterface>
	</joint>
	<actuator name="link_3_motor">
		<hardwareInterface>hardware_interface/PositionJointInterface</hardwareInterface>
		<mechanicalReduction>1</mechanicalReduction>
	</actuator>
  </transmission>
  
    <transmission name="link_4_trans">
	<type>transmission_interface/SimpleTransmission</type>
	<joint name="J4">
		<hardwareInterface>hardware_interface/PositionJointInterface</hardwareInterface>
	</joint>
	<actuator name="link_4_motor">
		<hardwareInterface>hardware_interface/PositionJointInterface</hardwareInterface>
		<mechanicalReduction>1</mechanicalReduction>
	</actuator>
  </transmission>
  
    <transmission name="link_5_trans">
	<type>transmission_interface/SimpleTransmission</type>
	<joint name="J5">
		<hardwareInterface>hardware_interface/PositionJointInterface</hardwareInterface>
	</joint>
	<actuator name="link_5_motor">
		<hardwareInterface>hardware_interface/PositionJointInterface</hardwareInterface>
		<mechanicalReduction>1</mechanicalReduction>
	</actuator>
  </transmission>
  
    <transmission name="link_6_trans">
	<type>transmission_interface/SimpleTransmission</type>
	<joint name="J6">
		<hardwareInterface>hardware_interface/PositionJointInterface</hardwareInterface>
	</joint>
	<actuator name="link_6_motor">
		<hardwareInterface>hardware_interface/PositionJointInterface</hardwareInterface>
		<mechanicalReduction>1</mechanicalReduction>
	</actuator>
  </transmission>
  
    <transmission name="Claw_1_trans">
	<type>transmission_interface/SimpleTransmission</type>
	<joint name="J7">
		<hardwareInterface>hardware_interface/PositionJointInterface</hardwareInterface>
	</joint>
	<actuator name="Claw_1_motor">
		<hardwareInterface>hardware_interface/PositionJointInterface</hardwareInterface>
		<mechanicalReduction>1</mechanicalReduction>
	</actuator>
  </transmission>
  
    <transmission name="Claw_2_trans">
	<type>transmission_interface/SimpleTransmission</type>
	<joint name="J8">
		<hardwareInterface>hardware_interface/PositionJointInterface</hardwareInterface>
	</joint>
	<actuator name="Claw_2_motor">
		<hardwareInterface>hardware_interface/PositionJointInterface</hardwareInterface>
		<mechanicalReduction>1</mechanicalReduction>
	</actuator>
  </transmission>
  
  <gazebo>
	<plugin name="control" filename="libgazebo_ros_control.so">
		<robotNamespace>/</robotNamespace>
	</plugin>
  </gazebo>
  
  <gazebo reference="L1">
	<selfCollide>true</selfCollide>
  </gazebo>
  
  <gazebo reference="L2">
	<selfCollide>true</selfCollide>
  </gazebo>
  
  <gazebo reference="L3">
	<selfCollide>true</selfCollide>
  </gazebo>
  
  <gazebo reference="L4">
	<selfCollide>true</selfCollide>
  </gazebo>
  
  <gazebo reference="L5">
	<selfCollide>true</selfCollide>
  </gazebo>
  
  <gazebo reference="L6">
	<selfCollide>true</selfCollide>
  </gazebo>
  
  <gazebo reference="Claw_1">
	<selfCollide>true</selfCollide>
  </gazebo>
  
  <gazebo reference="CLaw_2">
	<selfCollide>true</selfCollide>
  </gazebo>
  
<gazebo reference="camera_link">
  <sensor type="depth" name="camera_sensor">
    <pose>0 0 0 0 0 0</pose>
    <visualize>true</visualize>
    <update_rate>30</update_rate>
    <camera>
      <horizontal_fov>0.698</horizontal_fov>
      <image>
        <width>640</width>
        <height>480</height>
        <format>R8G8B8</format>
      </image>
      <clip>
        <near>0.1</near>
        <far>100</far>
      </clip>
      <depth_camera>
        <near>0.1</near>
        <far>100</far>
      </depth_camera>
    </camera>
    <plugin name="depth_camera_controller" filename="libgazebo_ros_depth_camera.so">
      <always_on>true</always_on>
      <update_rate>30.0</update_rate>
      <camera_name>robot_camera</camera_name>
      <image_topic_name>/camera/image_raw</image_topic_name>
      <camera_info_topic_name>/camera/camera_info</camera_info_topic_name>
      <depth_image_topic_name>/camera/depth/image_raw</depth_image_topic_name>
      <frame_name>camera_link</frame_name>
    </plugin>
  </sensor>
</gazebo>                                                                                                                                                  <gazebo reference="camera_link">
  <sensor name="fake_rgb_camera" type="camera">
    <pose>0 0 0 0 0 0</pose> <!-- Giống sensor thật -->
    <always_on>true</always_on>
    <update_rate>0.1</update_rate> <!-- Rất thấp -->
    <camera>
      <horizontal_fov>0.698</horizontal_fov> <!-- Copy y chang -->
      <image>
        <width>1</width> <!-- Nhỏ tẹo -->
        <height>1</height>
        <format>R8G8B8</format>
      </image>
      <clip>
        <near>0.1</near> <!-- Copy từ sensor thật -->
        <far>100</far>
      </clip>
    </camera>
    <visualize>true</visualize> <!-- Quan trọng: để Gazebo vẽ cái nón -->
  </sensor>
</gazebo>

</robot>
